{"stream":"btcusdt@depth","data":{"e":"depthUpdate","E":1721818629954,"T":1721818629945,"s":"BTCUSDT","U":5013778508814,"u":5013778513598,"pu":5013778508754,"b":[["1000.00","623.302"],["5000.00","4.274"],["10000.00","111.527"],["17223.60","0.021"],["33000.00","3.650"],["33231.60","0.004"],["59816.80","0.008"],["65287.00","0.306"],["65366.50","9.926"],["65738.90","4.262"],["65831.70","4.122"],["65832.00","3.623"],["66163.10","0.002"],["66260.40","0.009"],["66260.50","0.003"],["66263.10","0.000"],["66285.70","0.320"],["66287.10","0.003"],["66396.10","0.002"],["66396.60","0.300"],["66403.90","0.783"],["66410.10","0.000"],["66410.20","0.000"],["66411.90","38.785"],["66412.00","0.039"],["66412.50","0.000"],["66413.30","1.341"],["66413.90","0.907"],["66423.90","0.180"],["66426.50","1.460"],["66429.90","1.770"],["66436.80","1.685"],["66438.10","0.010"],["66438.20","0.010"],["66439.30","0.000"],["66441.60","3.015"],["66441.70","0.806"],["66441.80","0.014"],["66445.00","1.756"],["66445.60","0.002"],["66446.00","0.092"],["66446.80","1.342"],["66447.90","0.235"],["66448.10","0.669"],["66448.20","0.008"],["66456.50","0.016"],["66457.10","0.000"],["66458.00","0.199"],["66461.20","0.000"],["66462.70","0.000"],["66463.10","9.831"]],"a":[["66463.20","3.956"],["66466.50","0.170"],["66466.80","0.219"],["66466.90","0.394"],["66467.00","0.167"],["66467.10","0.644"],["66467.20","0.517"],["66467.50","0.458"],["66467.60","0.460"],["66469.20","0.089"],["66469.80","0.058"],["66475.20","0.002"],["66475.30","0.004"],["66485.10","0.101"],["66485.80","0.830"],["66486.30","0.000"],["66503.00","0.012"],["66503.10","0.035"],["66504.20","0.030"],["66506.40","0.036"],["66507.10","0.093"],["66509.70","1.348"],["66511.00","0.107"],["66511.10","0.009"],["66511.20","46.489"],["66515.00","0.000"],["66516.40","0.518"],["66518.10","1.706"],["66519.40","0.182"],["66519.70","0.109"],["66743.00","0.233"],["66763.20","0.452"],["67200.00","54.253"],["67383.90","1.631"],["67500.00","47.707"],["67900.00","47.714"]]}}
{"stream":"btcusdt@depth","data":{"e":"depthUpdate","E":1721818630208,"T":1721818630205,"s":"BTCUSDT","U":5013778513795,"u":5013778522666,"pu":5013778513598,"b":[["1000.00","623.302"],["5000.00","4.254"],["17223.60","0.021"],["33000.00","3.646"],["33231.60","0.004"],["59816.80","0.004"],["63804.60","0.087"],["64894.30","0.000"],["65090.60","0.000"],["65286.90","0.002"],["65483.20","0.003"],["65539.30","6.123"],["65679.50","0.000"],["65680.10","0.225"],["65738.70","8.175"],["65765.50","0.004"],["65795.80","0.046"],["65832.00","3.342"],["65853.00","0.554"],["65875.80","0.044"],["65875.90","0.000"],["66071.60","0.043"],["66072.20","0.000"],["66130.80","2.359"],["66267.30","0.039"],["66268.50","0.000"],["66362.60","0.000"],["66408.60","0.005"],["66408.70","0.000"],["66409.60","2.315"],["66409.90","0.435"],["66410.30","0.012"],["66411.90","38.410"],["66412.00","0.039"],["66415.20","0.000"],["66419.90","0.023"],["66423.50","0.035"],["66426.50","1.460"],["66427.30","1.685"],["66429.90","1.788"],["66430.00","0.079"],["66430.30","0.046"],["66434.10","0.045"],["66436.20","1.699"],["66436.50","0.000"],["66436.80","0.000"],["66436.90","1.040"],["66437.60","0.089"],["66438.20","0.003"],["66439.30","0.007"],["66440.20","1.685"],["66440.60","0.000"],["66442.40","0.009"],["66442.60","0.000"],["66443.00","0.004"],["66444.20","0.000"],["66445.00","0.011"],["66446.00","1.837"],["66446.80","0.000"],["66447.60","0.039"],["66447.90","0.232"],["66448.20","0.821"],["66448.50","0.030"],["66449.50","0.405"],["66450.10","1.341"],["66451.20","0.031"],["66451.30","0.004"],["66458.30","0.000"],["66458.60","0.000"],["66463.10","9.806"]],"a":[["66463.10","0.000"],["66463.20","4.256"],["66463.90","0.151"],["66465.10","0.022"],["66466.70","0.225"],["66467.00","0.392"],["66467.30","0.179"],["66468.00","0.044"],["66469.00","0.000"],["66469.10","0.300"],["66469.20","0.085"],["66469.30","0.002"],["66469.40","0.662"],["66469.60","0.846"],["66469.70","0.033"],["66470.00","0.080"],["66471.20","0.034"],["66471.40","0.190"],["66471.50","0.027"],["66472.20","0.023"],["66473.00","0.002"],["66473.20","0.015"],["66473.80","0.315"],["66474.50","0.016"],["66474.80","0.002"],["66474.90","0.601"],["66475.10","1.404"],["66475.30","0.000"],["66475.70","0.038"],["66478.00","0.004"],["66478.60","0.004"],["66479.80","0.666"],["66480.30","0.043"],["66482.00","3.544"],["66484.50","0.006"],["66485.70","0.002"],["66487.70","0.000"],["66488.50","0.121"],["66491.00","0.027"],["66493.10","0.172"],["66493.30","0.000"],["66494.70","0.014"],["66495.00","0.000"],["66497.70","0.035"],["66498.40","1.130"],["66498.50","1.684"],["66498.70","0.002"],["66499.20","0.002"],["66499.70","0.002"],["66500.80","1.699"],["66501.50","0.000"],["66502.80","0.000"],["66503.00","0.000"],["66503.10","0.017"],["66503.30","0.477"],["66503.70","0.127"],["66503.90","1.809"],["66504.20","0.023"],["66504.60","0.009"],["66504.90","0.007"],["66505.30","0.003"],["66506.10","0.030"],["66506.20","0.602"],["66509.60","0.000"],["66511.10","1.685"],["66511.20","46.588"],["66513.00","0.284"],["66515.10","0.013"],["66515.30","0.007"],["66516.10","0.054"],["66516.20","0.142"],["66516.30","0.120"],["66518.10","0.000"],["66519.40","0.182"],["66529.30","0.004"],["66543.30","0.000"],["66661.10","1.080"],["66661.50","0.013"],["66857.40","0.050"],["67053.70","0.054"],["67073.00","0.240"],["67094.90","0.302"],["67241.10","0.887"],["67250.10","0.002"],["67446.40","0.000"],["67642.70","0.002"],["67839.00","0.229"],["67875.00","0.178"],["68035.30","0.000"],["76432.60","0.003"]]}}
{"stream":"btcusdt@depth","data":{"e":"depthUpdate","E":1721818630461,"T":1721818630447,"s":"BTCUSDT","U":5013778522773,"u":5013778531761,"pu":5013778522666,"b":[["1000.00","623.302"],["5000.00","4.274"],["17223.60","0.021"],["33000.00","3.646"],["59816.80","0.004"],["64897.10","0.056"],["65092.80","0.040"],["65288.60","0.039"],["65484.30","0.054"],["65738.90","3.654"],["65765.50","0.004"],["65831.70","4.403"],["66130.80","2.349"],["66362.30","0.034"],["66397.10","0.002"],["66409.90","0.442"],["66410.50","0.724"],["66415.10","0.068"],["66426.50","1.454"],["66454.50","0.182"],["66454.60","0.000"],["66462.70","0.000"],["66462.90","0.002"],["66463.00","0.209"],["66463.10","9.802"]],"a":[["66463.90","0.000"],["66469.10","0.000"],["66469.70","0.029"],["66470.90","0.004"],["66471.00","0.901"],["66473.20","0.015"],["66474.70","0.038"],["66474.80","0.302"],["66475.00","0.318"],["66488.10","0.090"],["66495.10","0.217"],["66509.70","1.348"],["66511.80","0.895"],["66517.00","0.085"],["66544.30","0.015"],["66663.20","0.003"],["67240.80","2.330"],["67445.20","0.000"],["76432.60","0.018"],["78345.80","0.145"]]}}
{"stream":"btcusdt@depth","data":{"e":"depthUpdate","E":1721818630712,"T":1721818630711,"s":"BTCUSDT","U":5013778532184,"u":5013778541232,"pu":5013778531761,"b":[["1000.00","623.302"],["5000.00","4.254"],["17223.60","0.021"],["33000.00","3.650"],["63139.90","0.004"],["65233.50","7.892"],["65652.50","0.002"],["65685.50","3.037"],["65738.70","8.783"],["65862.30","0.088"],["66130.80","2.359"],["66260.20","0.918"],["66340.80","0.224"],["66394.00","0.336"],["66396.10","0.000"],["66398.10","0.023"],["66407.90","0.000"],["66408.00","0.006"],["66409.90","0.007"],["66410.10","38.131"],["66411.90","0.279"],["66412.00","0.039"],["66412.10","0.000"],["66412.40","17.185"],["66412.50","0.002"],["66413.30","1.305"],["66426.50","1.016"],["66429.20","0.630"],["66429.50","0.062"],["66429.90","0.784"],["66441.80","1.376"],["66448.60","0.051"],["66449.50","0.003"],["66450.40","0.004"],["66451.30","0.004"],["66452.20","0.002"],["66453.10","2.038"],["66456.50","0.018"],["66458.60","0.005"],["66463.10","9.838"]],"a":[["66463.20","4.312"],["66464.90","0.318"],["66466.50","0.170"],["66466.70","0.000"],["66474.90","0.601"],["66476.60","0.023"],["66477.80","0.000"],["66483.10","0.020"],["66484.10","0.171"],["66485.80","0.827"],["66486.30","0.003"],["66486.50","0.018"],["66493.10","0.154"],["66509.70","1.043"],["66516.40","0.084"],["66529.20","0.137"],["66658.90","0.070"],["66854.60","0.041"],["67000.00","53.386"],["67050.40","0.038"],["67246.10","0.193"],["67440.20","2.663"],["67441.90","2.708"]]}}
{"stream":"btcusdt@depth","data":{"e":"depthUpdate","E":1721818630967,"T":1721818630966,"s":"BTCUSDT","U":5013778541322,"u":5013778550410,"pu":5013778541232,"b":[["1000.00","623.302"],["5000.00","4.274"],["17223.60","0.021"],["33000.00","3.646"],["33231.60","0.004"],["59809.90","0.003"],["59817.20","0.002"],["63139.00","0.010"],["63139.90","0.006"],["65645.60","1.099"],["66120.00","3.027"],["66130.80","2.359"],["66163.10","0.002"],["66263.10","0.000"],["66309.70","0.002"],["66338.70","0.124"],["66396.10","0.002"],["66408.00","0.004"],["66409.00","0.083"],["66409.20","39.209"],["66410.10","0.000"],["66410.20","0.000"],["66410.50","0.724"],["66412.00","0.037"],["66412.10","0.002"],["66412.40","0.004"],["66412.50","0.000"],["66412.60","0.004"],["66413.30","1.305"],["66426.50","1.889"],["66429.90","1.963"],["66439.30","0.000"],["66441.90","0.069"],["66446.00","0.092"],["66446.80","1.745"],["66447.60","0.039"],["66449.10","0.002"],["66449.50","0.400"],["66450.50","0.727"],["66450.90","0.019"],["66452.90","0.000"],["66456.40","0.000"],["66459.80","0.009"],["66460.40","0.468"],["66461.90","0.003"],["66462.30","0.120"],["66462.70","0.000"],["66462.80","0.208"],["66462.90","0.002"],["66463.10","9.685"],["66500.00","0.000"]],"a":[["66463.20","0.886"],["66465.00","0.000"],["66465.80","0.000"],["66466.50","0.000"],["66466.70","0.000"],["66466.80","0.000"],["66466.90","0.000"],["66467.00","0.000"],["66467.10","0.030"],["66467.20","0.002"],["66467.30","0.175"],["66467.50","0.000"],["66467.70","0.352"],["66468.00","0.042"],["66468.90","0.000"],["66469.00","0.006"],["66469.20","0.023"],["66469.30","0.302"],["66469.40","0.058"],["66469.80","0.049"],["66469.90","1.109"],["66470.00","0.080"],["66470.90","0.000"],["66471.00","0.300"],["66471.10","1.206"],["66471.50","0.027"],["66472.00","0.637"],["66472.20","0.021"],["66473.00","0.153"],["66473.70","0.213"],["66475.00","0.018"],["66475.70","0.035"],["66476.90","0.003"],["66477.00","0.121"],["66477.50","0.125"],["66478.30","0.073"],["66478.60","0.000"],["66479.20","0.199"],["66479.60","0.025"],["66479.80","0.370"],["66480.10","0.046"],["66480.20","1.440"],["66481.10","0.033"],["66483.10","0.002"],["66485.40","0.023"],["66485.90","0.737"],["66486.50","0.000"],["66487.30","0.571"],["66488.00","0.572"],["66493.90","0.666"],["66495.10","0.202"],["66498.20","0.153"],["66498.50","0.000"],["66499.00","0.300"],["66499.70","1.686"],["66503.10","0.035"],["66503.30","0.066"],["66503.90","1.797"],["66504.90","0.019"],["66505.90","0.027"],["66506.20","0.600"],["66508.90","0.146"],["66509.10","0.036"],["66509.70","1.342"],["66510.90","43.014"],["66511.10","1.721"],["66511.20","3.704"],["66511.80","0.865"],["66525.60","0.105"],["66591.30","0.004"],["66599.90","4.270"],["66662.60","0.000"],["66763.20","0.452"],["67637.60","0.038"],["67833.40","0.038"],["68029.10","0.040"]]}}
{"stream":"btcusdt@depth","data":{"e":"depthUpdate","E":1721818631219,"T":1721818631216,"s":"BTCUSDT","U":5013778550498,"u":5013778564362,"pu":5013778550410,"b":[["1000.00","623.302"],["5000.00","4.274"],["17223.60","0.021"],["64469.30","0.146"],["65832.00","2.303"],["66073.00","0.006"],["66130.80","2.359"],["66239.90","0.161"],["66240.00","0.776"],["66260.50","0.003"],["66285.30","0.000"],["66288.20","1.461"],["66400.10","0.009"],["66405.70","0.228"],["66406.00","2.468"],["66406.10","0.028"],["66409.00","0.083"],["66409.10","0.039"],["66409.20","1.437"],["66409.50","0.034"],["66409.60","2.315"],["66409.90","0.158"],["66411.90","38.051"],["66412.00","0.039"],["66412.10","0.000"],["66412.20","0.730"],["66412.30","2.767"],["66412.40","0.004"],["66412.50","0.000"],["66412.60","0.004"],["66412.70","0.002"],["66412.80","0.060"],["66412.90","0.002"],["66413.00","0.603"],["66413.10","0.000"],["66417.00","1.189"],["66417.30","1.387"],["66417.50","1.397"],["66423.50","0.035"],["66426.50","1.889"],["66427.30","0.000"],["66428.10","0.853"],["66428.80","1.690"],["66429.70","0.054"],["66430.00","0.079"],["66430.30","0.046"],["66434.10","1.085"],["66434.30","0.676"],["66434.40","0.057"],["66435.20","0.029"],["66435.40","0.163"],["66436.20","0.007"],["66436.50","0.000"],["66436.60","0.000"],["66436.80","0.000"],["66436.90","0.000"],["66437.40","0.839"],["66438.10","0.017"],["66438.40","1.687"],["66439.10","0.033"],["66439.30","0.007"],["66440.20","0.000"],["66440.30","0.002"],["66440.60","0.007"],["66441.10","0.069"],["66441.90","0.062"],["66442.00","0.061"],["66442.10","0.030"],["66442.40","1.687"],["66442.50","0.009"],["66443.00","0.004"],["66444.20","0.000"],["66444.70","0.100"],["66446.80","0.000"],["66447.20","1.936"],["66447.60","0.036"],["66447.80","0.032"],["66448.30","0.005"],["66448.50","0.030"],["66449.30","0.000"],["66449.90","0.003"],["66450.10","1.314"],["66450.20","0.031"],["66450.50","0.724"],["66450.90","0.017"],["66451.20","0.004"],["66451.40","0.049"],["66452.40","0.002"],["66454.60","0.000"],["66456.40","0.430"],["66459.90","0.223"],["66460.70","0.000"]],"a":[["66463.20","1.704"],["66463.30","0.065"],["66464.40","0.444"],["66464.50","0.447"],["66464.60","0.443"],["66464.70","0.449"],["66465.10","0.017"],["66466.20","0.168"],["66466.50","0.228"],["66466.90","0.230"],["66467.00","0.394"],["66467.10","0.418"],["66467.20","0.166"],["66467.50","0.172"],["66467.60","0.000"],["66468.00","0.046"],["66469.00","0.000"],["66469.40","0.959"],["66469.70","0.029"],["66469.80","0.059"],["66470.00","0.082"],["66470.30","0.003"],["66471.10","1.203"],["66471.20","0.034"],["66471.30","0.034"],["66471.40","0.192"],["66471.50","0.000"],["66472.00","0.633"],["66472.10","0.370"],["66473.70","0.211"],["66473.80","0.015"],["66475.10","0.789"],["66475.50","0.235"],["66475.60","0.848"],["66476.70","0.104"],["66476.90","0.000"],["66479.20","0.210"],["66480.10","0.045"],["66481.20","0.004"],["66481.40","0.080"],["66481.60","0.601"],["66482.00","3.544"],["66482.10","0.044"],["66482.80","0.240"],["66483.80","0.152"],["66484.50","0.003"],["66484.60","1.861"],["66484.80","0.077"],["66487.10","0.672"],["66488.50","0.121"],["66488.70","0.669"],["66491.00","0.023"],["66492.10","0.061"],["66494.10","0.027"],["66495.00","0.000"],["66498.90","1.686"],["66499.20","0.002"],["66499.70","0.002"],["66500.60","1.686"],["66500.80","0.015"],["66501.50","0.000"],["66503.30","0.073"],["66504.00","0.171"],["66504.90","0.000"],["66506.40","0.036"],["66508.00","0.004"],["66509.90","0.033"],["66510.80","0.132"],["66510.90","0.003"],["66511.00","0.031"],["66511.10","1.721"],["66511.20","46.715"],["66513.00","0.870"],["66513.20","0.008"],["66513.30","0.056"],["66513.40","0.452"],["66513.50","0.065"],["66513.60","0.000"],["66513.70","0.000"],["66513.80","0.646"],["66513.90","0.214"],["66514.00","0.038"],["66514.10","0.074"],["66514.90","0.000"],["66515.00","0.000"],["66515.30","0.000"],["66515.70","0.070"],["66515.80","0.800"],["66515.90","0.006"],["66519.40","0.182"],["66526.90","1.012"],["66662.60","0.015"],["66735.70","0.009"],["67187.60","5.732"]]}}
{"stream":"btcusdt@depth","data":{"e":"depthUpdate","E":1721818631476,"T":1721818631476,"s":"BTCUSDT","U":5013778564676,"u":5013778582232,"pu":5013778564362,"b":[["1000.00","623.302"],["5000.00","4.274"],["17223.60","0.021"],["33000.00","3.646"],["59816.80","0.006"],["59816.90","0.002"],["65645.90","0.281"],["65831.70","5.442"],["66073.10","0.117"],["66274.90","0.020"],["66338.70","0.124"],["66377.10","0.000"],["66378.40","0.237"],["66378.50","0.500"],["66379.10","0.065"],["66384.00","0.033"],["66387.90","1.693"],["66400.10","0.018"],["66406.00","2.445"],["66408.70","0.000"],["66409.10","0.030"],["66409.60","2.315"],["66411.90","0.279"],["66412.00","0.037"],["66412.10","0.000"],["66412.40","0.004"],["66412.50","0.000"],["66412.60","37.776"],["66412.70","0.004"],["66412.80","0.060"],["66412.90","0.002"],["66413.00","0.603"],["66413.10","0.000"],["66413.40","0.861"],["66423.50","1.720"],["66426.50","1.305"],["66426.90","0.013"],["66427.80","0.473"],["66428.10","0.000"],["66428.80","0.005"],["66429.90","1.945"],["66430.00","0.645"],["66430.30","0.899"],["66432.70","0.023"],["66433.90","0.024"],["66434.10","0.045"],["66434.40","0.000"],["66434.90","0.025"],["66435.20","0.027"],["66435.30","0.309"],["66435.40","0.010"],["66435.70","0.000"],["66436.20","0.000"],["66436.50","0.000"],["66436.60","1.685"],["66436.70","1.211"],["66437.20","0.091"],["66437.80","0.030"],["66437.90","0.030"],["66438.10","0.010"],["66438.30","0.053"],["66438.40","0.002"],["66438.50","0.090"],["66438.80","0.092"],["66439.10","0.033"],["66439.20","0.000"],["66439.30","1.685"],["66439.40","0.155"],["66439.90","0.079"],["66440.60","0.000"],["66441.00","1.238"],["66441.20","1.491"],["66441.50","0.000"],["66441.60","0.055"],["66441.80","0.014"],["66441.90","0.044"],["66442.00","0.081"],["66442.20","0.108"],["66442.40","0.082"],["66443.20","0.000"],["66443.30","0.000"],["66443.80","0.031"],["66443.90","0.018"],["66444.40","0.030"],["66444.50","0.046"],["66445.00","0.034"],["66445.50","3.012"],["66445.60","0.059"],["66446.20","1.745"],["66446.30","0.086"],["66446.60","0.037"],["66447.10","0.400"],["66447.20","0.040"],["66447.40","0.002"],["66447.50","0.744"],["66447.70","0.591"],["66447.80","0.514"],["66448.00","0.030"],["66448.10","0.594"],["66448.20","0.008"],["66448.40","0.755"],["66448.50","0.000"],["66448.80","3.069"],["66448.90","0.846"],["66449.30","0.780"],["66449.50","0.000"],["66449.60","0.000"],["66449.70","0.714"],["66449.90","0.000"],["66450.00","0.849"],["66450.20","0.182"],["66450.30","0.108"],["66450.40","0.000"],["66450.50","0.564"],["66450.60","0.165"],["66450.70","1.364"],["66450.80","0.332"],["66451.00","0.197"],["66451.10","0.235"],["66451.50","0.000"],["66451.60","0.020"],["66451.90","0.175"],["66452.40","0.015"],["66453.00","0.199"],["66453.10","2.028"],["66453.20","0.008"],["66453.30","0.000"],["66453.40","0.374"],["66453.50","0.017"],["66453.80","0.469"],["66453.90","0.000"],["66454.00","0.006"],["66454.20","0.401"],["66454.30","0.012"],["66454.40","1.237"],["66454.50","0.197"],["66454.60","0.558"],["66454.70","0.789"],["66454.80","0.099"],["66454.90","0.075"],["66455.00","0.000"],["66455.40","0.000"],["66456.40","0.000"],["66456.60","0.002"],["66456.80","0.124"],["66457.00","0.586"],["66457.10","0.000"],["66457.30","0.350"],["66457.70","0.181"],["66459.20","0.000"],["66459.50","0.144"],["66459.90","0.074"],["66460.00","0.050"],["66460.30","0.149"],["66460.40","0.000"],["66460.50","0.000"],["66460.90","0.000"],["66461.90","0.100"],["66462.90","0.002"],["66463.00","0.004"],["66463.10","1.560"],["66463.20","1.471"],["66463.30","0.000"],["66463.40","0.000"],["66463.50","0.000"],["66463.60","0.000"],["66463.70","0.000"],["66463.80","0.000"],["66463.90","0.000"],["66464.00","0.002"],["66464.10","0.000"],["66464.20","0.209"],["66464.30","16.273"],["66464.80","0.000"]],"a":[["66463.20","0.000"],["66463.30","0.000"],["66464.00","0.000"],["66464.30","0.000"],["66464.40","2.025"],["66464.50","0.000"],["66464.60","0.002"],["66464.70","0.000"],["66466.10","0.000"],["66466.20","0.017"],["66466.50","0.000"],["66466.80","0.000"],["66466.90","0.000"],["66467.00","0.000"],["66467.10","0.000"],["66467.20","0.002"],["66467.30","0.031"],["66467.50","0.000"],["66467.60","0.170"],["66467.70","0.456"],["66467.80","0.600"],["66467.90","0.640"],["66468.00","0.002"],["66468.40","0.059"],["66468.50","0.226"],["66468.90","0.002"],["66469.00","0.443"],["66469.10","0.616"],["66469.20","0.192"],["66469.30","0.176"],["66469.40","0.613"],["66469.60","0.936"],["66469.70","0.178"],["66469.80","0.038"],["66469.90","0.679"],["66470.00","0.080"],["66470.30","0.350"],["66470.40","0.002"],["66470.50","0.002"],["66471.00","0.330"],["66471.10","1.633"],["66471.20","0.016"],["66471.30","0.032"],["66472.10","0.438"],["66472.20","0.021"],["66472.30","0.895"],["66472.50","0.614"],["66472.60","0.000"],["66472.70","0.012"],["66472.90","0.000"],["66473.10","0.000"],["66473.20","0.000"],["66473.30","0.865"],["66473.40","0.011"],["66473.50","0.000"],["66473.60","0.048"],["66473.70","0.061"],["66473.80","0.300"],["66474.00","0.128"],["66474.20","0.002"],["66474.30","0.015"],["66474.40","0.032"],["66474.60","0.000"],["66474.70","0.038"],["66474.80","0.002"],["66474.90","0.000"],["66475.00","0.318"],["66475.10","0.012"],["66475.30","0.306"],["66475.50","0.210"],["66476.00","0.167"],["66476.20","0.015"],["66476.50","0.072"],["66476.70","0.014"],["66476.80","1.353"],["66477.00","0.018"],["66477.20","0.002"],["66477.60","0.333"],["66478.20","0.037"],["66478.30","0.034"],["66478.40","0.046"],["66478.80","0.090"],["66479.00","0.195"],["66479.30","0.064"],["66479.60","0.100"],["66479.90","0.640"],["66480.30","0.118"],["66480.50","0.006"],["66480.90","0.601"],["66481.10","0.007"],["66481.20","0.601"],["66481.50","2.714"],["66483.80","0.363"],["66484.70","0.000"],["66484.80","0.057"],["66484.90","0.097"],["66485.00","0.923"],["66485.10","0.121"],["66485.90","0.734"],["66486.10","0.003"],["66486.40","0.523"],["66486.50","0.003"],["66487.10","0.032"],["66487.80","0.005"],["66488.00","0.487"],["66488.70","1.454"],["66488.80","0.677"],["66489.00","0.102"],["66489.30","0.686"],["66489.50","0.732"],["66491.30","0.466"],["66492.90","0.026"],["66493.20","3.044"],["66493.90","0.663"],["66494.60","0.861"],["66496.40","0.000"],["66497.00","0.224"],["66497.40","0.054"],["66497.50","0.053"],["66498.30","0.000"],["66498.90","0.002"],["66499.50","0.308"],["66500.80","1.699"],["66503.10","0.017"],["66503.30","0.066"],["66504.00","0.925"],["66504.90","0.019"],["66507.90","0.031"],["66508.90","0.131"],["66509.10","0.051"],["66509.70","1.342"],["66509.80","0.846"],["66509.90","0.026"],["66510.80","0.132"],["66510.90","0.047"],["66511.00","0.031"],["66511.10","0.038"],["66511.20","46.715"],["66513.20","0.008"],["66514.80","0.000"],["66515.00","0.007"],["66515.60","1.746"],["66515.70","0.070"],["66519.40","0.182"],["66524.50","0.898"],["66525.60","0.075"],["66526.90","0.591"],["66536.40","0.000"],["66537.30","0.037"],["66543.20","0.035"],["66546.00","0.078"],["66547.20","0.682"],["66548.00","0.030"],["66600.80","0.000"],["66600.90","0.031"],["66614.40","1.204"],["66662.60","0.015"],["66663.20","0.003"],["66664.00","0.303"],["66667.30","0.005"],["66667.40","0.039"],["66680.90","1.240"],["66691.70","0.015"],["66735.40","0.105"],["67454.60","0.726"],["73094.50","0.000"],["73113.90","0.002"],["73658.50","0.094"],["99694.80","0.000"],["99695.00","0.004"]]}}
{"stream":"btcusdt@depth","data":{"e":"depthUpdate","E":1721818631727,"T":1721818631726,"s":"BTCUSDT","U":5013778582238,"u":5013778593387,"pu":5013778582232,"b":[["1000.00","623.302"],["5000.00","4.274"],["17223.60","0.021"],["33000.00","3.646"],["59806.30","0.000"],["59816.80","0.004"],["59820.70","0.006"],["59833.00","0.018"],["65017.90","0.000"],["65029.00","0.010"],["65133.80","0.306"],["65286.70","0.590"],["65365.20","3.606"],["65471.50","2.989"],["65938.00","0.004"],["66130.80","2.359"],["66260.50","0.003"],["66394.00","0.103"],["66395.60","1.794"],["66396.80","0.017"],["66409.90","0.007"],["66411.90","0.000"],["66412.40","0.002"],["66413.90","17.906"],["66414.00","0.037"],["66414.10","0.000"],["66414.20","0.002"],["66414.30","2.410"],["66414.40","0.000"],["66414.50","0.155"],["66422.40","8.034"],["66425.70","0.071"],["66436.20","0.007"],["66437.00","0.182"],["66437.30","0.338"],["66437.80","0.023"],["66443.70","0.020"],["66443.90","0.039"],["66446.80","1.364"],["66447.80","0.032"],["66450.30","0.078"],["66452.30","0.030"],["66453.00","0.002"],["66453.10","0.758"],["66453.40","0.002"],["66454.20","0.598"],["66454.30","1.284"],["66454.40","0.392"],["66454.60","0.932"],["66455.00","0.578"],["66457.60","0.430"],["66457.70","0.186"],["66460.30","0.000"],["66461.00","0.360"],["66461.90","0.155"],["66462.40","0.005"],["66463.10","1.124"],["66463.20","1.468"],["66464.30","16.454"]],"a":[["66464.40","2.540"],["66466.40","0.026"],["66467.20","0.170"],["66467.30","0.121"],["66467.40","0.214"],["66467.50","0.167"],["66467.60","0.170"],["66467.70","0.636"],["66468.20","0.108"],["66468.40","0.329"],["66469.10","0.449"],["66469.20","0.023"],["66469.30","0.006"],["66469.40","0.603"],["66469.80","0.024"],["66471.00","0.339"],["66471.60","0.586"],["66472.40","0.321"],["66472.80","0.000"],["66473.90","0.645"],["66474.30","0.097"],["66474.50","0.005"],["66474.80","0.101"],["66475.20","0.605"],["66475.30","0.302"],["66476.10","0.010"],["66476.70","0.009"],["66477.80","0.005"],["66477.90","0.645"],["66479.20","0.173"],["66479.60","0.100"],["66482.10","0.204"],["66483.90","0.640"],["66484.10","0.412"],["66485.00","0.903"],["66485.10","0.101"],["66485.20","0.045"],["66485.30","1.385"],["66488.20","0.060"],["66488.30","3.107"],["66493.10","0.150"],["66502.70","0.608"],["66510.90","0.057"],["66514.40","1.440"],["66514.50","0.000"],["66547.20","0.265"],["66662.60","0.000"],["66663.80","0.015"],["67097.00","0.000"],["67192.60","0.000"],["67245.80","0.000"],["67388.30","0.445"],["67418.70","0.000"],["67889.00","0.002"],["73098.70","0.005"],["73112.80","0.006"],["76432.60","0.000"],["76434.00","0.018"]]}}
{"stream":"btcusdt@depth","data":{"e":"depthUpdate","E":1721818631980,"T":1721818631975,"s":"BTCUSDT","U":5013778593507,"u":5013778602543,"pu":5013778593387,"b":[["1000.00","623.302"],["5000.00","4.274"],["17223.60","0.021"],["63139.90","0.004"],["65366.50","10.828"],["65620.40","0.222"],["65819.80","0.000"],["66130.80","2.359"],["66164.30","0.008"],["66264.30","0.000"],["66400.00","5.916"],["66405.70","0.048"],["66406.40","0.207"],["66413.60","0.000"],["66413.70","0.217"],["66413.80","1.203"],["66413.90","17.906"],["66414.00","0.037"],["66414.10","0.000"],["66414.20","0.002"],["66414.30","2.410"],["66438.60","0.042"],["66438.70","0.204"],["66438.80","0.012"],["66441.90","0.064"],["66442.00","0.161"],["66442.20","0.068"],["66442.40","0.002"],["66443.70","0.000"],["66443.90","0.018"],["66445.00","1.779"],["66446.20","0.000"],["66456.70","0.144"],["66459.50","0.000"],["66463.10","0.343"],["66463.20","1.462"],["66464.30","17.496"]],"a":[["66464.40","2.535"],["66466.40","0.000"],["66467.20","0.002"],["66467.40","0.047"],["66467.50","0.000"],["66467.60","0.000"],["66467.70","0.654"],["66471.00","0.340"],["66474.40","0.058"],["66482.10","0.186"],["66484.10","0.430"],["66486.70","0.383"],["66486.80","0.097"],["66487.90","1.488"],["66495.40","0.025"],["66512.60","0.023"],["66514.40","1.440"],["66514.50","0.000"],["66514.60","0.000"],["66514.70","0.037"],["66514.80","0.002"],["66514.90","0.000"],["66591.30","0.002"],["66600.90","0.033"],["66663.80","0.015"],["66764.40","0.000"],["67089.20","0.149"],["67094.90","0.006"],["67095.80","0.743"],["67149.70","0.002"],["67247.90","0.010"],["67884.70","0.010"],["76434.00","0.033"]]}}
{"stream":"btcusdt@depth","data":{"e":"depthUpdate","E":1721818632234,"T":1721818632234,"s":"BTCUSDT","U":5013778602741,"u":5013778614295,"pu":5013778602543,"b":[["1000.00","623.302"],["5000.00","4.274"],["17223.60","0.021"],["33000.00","3.646"],["33232.20","0.000"],["59809.60","0.000"],["59819.50","0.012"],["63141.10","0.004"],["64469.30","0.143"],["64470.40","0.036"],["65839.80","0.683"],["65938.10","0.103"],["66130.80","2.349"],["66132.00","0.009"],["66240.00","0.376"],["66240.20","0.852"],["66306.40","0.000"],["66306.70","1.202"],["66397.80","1.882"],["66414.60","0.000"],["66415.80","0.010"],["66417.50","1.294"],["66417.80","0.103"],["66418.60","0.102"],["66419.80","0.007"],["66423.50","0.035"],["66424.40","0.432"],["66426.00","1.726"],["66427.70","0.116"],["66427.80","0.083"],["66429.90","1.794"],["66431.10","0.007"],["66434.10","0.045"],["66435.30","0.302"],["66436.20","1.692"],["66436.30","1.040"],["66436.60","0.000"],["66436.70","0.171"],["66437.70","0.043"],["66438.30","0.051"],["66440.10","0.000"],["66441.00","1.220"],["66441.30","0.415"],["66441.50","0.007"],["66442.50","0.002"],["66443.00","0.004"],["66449.70","0.714"],["66450.20","0.156"],["66450.70","1.364"],["66451.00","0.194"],["66451.40","0.020"],["66452.50","0.169"],["66454.30","1.317"],["66458.00","0.184"],["66461.00","0.211"],["66461.70","0.151"],["66461.90","0.100"],["66462.90","0.000"],["66463.00","0.000"],["66463.20","1.763"],["66464.10","0.002"],["66464.20","0.213"],["66464.30","17.498"]],"a":[["66464.40","2.533"],["66469.60","0.938"],["66471.00","0.339"],["66471.10","1.636"],["66471.20","0.014"],["66471.30","0.003"],["66471.40","0.163"],["66472.10","0.442"],["66472.30","0.892"],["66473.90","0.678"],["66474.00","0.124"],["66474.30","0.130"],["66482.00","3.544"],["66488.80","0.780"],["66497.70","0.058"],["66499.20","1.686"],["66500.80","0.015"],["66509.90","0.033"],["66511.10","1.721"],["66515.00","0.000"],["66515.60","0.063"],["66515.70","0.066"],["66516.90","0.041"],["66519.80","0.874"],["66521.00","0.127"],["66663.80","0.015"],["66798.60","0.000"],["67558.50","4.360"],["67691.40","0.589"],["68457.00","0.000"]]}}
{"stream":"btcusdt@depth","data":{"e":"depthUpdate","E":1721818632485,"T":1721818632476,"s":"BTCUSDT","U":5013778614301,"u":5013778627586,"pu":5013778614295,"b":[["1000.00","623.302"],["5000.00","4.274"],["17223.60","0.021"],["59817.90","0.002"],["63139.90","0.002"],["64470.40","0.054"],["64482.50","0.036"],["65685.80","0.608"],["65819.60","0.683"],["65853.00","0.354"],["65999.00","0.120"],["66132.00","0.019"],["66183.00","0.012"],["66260.20","0.034"],["66342.90","0.023"],["66380.10","0.066"],["66381.40","0.009"],["66382.20","0.084"],["66400.10","0.014"],["66401.40","0.057"],["66414.00","0.043"],["66420.00","0.025"],["66420.20","0.000"],["66421.10","0.025"],["66421.30","0.002"],["66438.50","0.210"],["66438.80","0.132"],["66439.40","0.155"],["66441.90","0.044"],["66442.00","0.021"],["66444.00","1.030"],["66450.20","0.156"],["66450.80","0.030"],["66450.90","0.319"],["66454.60","0.781"],["66455.20","0.154"],["66463.10","0.339"],["66464.20","0.255"],["66464.30","17.507"]],"a":[["66463.00","0.000"],["66467.30","0.203"],["66467.60","0.167"],["66467.70","0.546"],["66471.00","0.339"],["66479.60","0.100"],["66499.10","1.684"],["66499.20","0.002"],["66499.90","1.684"],["66500.60","0.002"],["66503.90","1.797"],["66504.50","0.019"],["66504.90","0.007"],["66601.10","1.212"],["66614.40","0.004"],["66663.80","0.015"],["66664.40","0.000"],["66667.60","1.200"],["66680.90","0.040"],["66743.00","0.133"],["67073.00","0.040"],["67561.00","0.913"]]}}
{"stream":"btcusdt@depth","data":{"e":"depthUpdate","E":1721818632738,"T":1721818632738,"s":"BTCUSDT","U":5013778627947,"u":5013778637886,"pu":5013778627586,"b":[["1000.00","623.302"],["5000.00","4.274"],["17223.60","0.021"],["33000.00","3.646"],["33231.60","0.000"],["33232.20","0.004"],["59816.70","0.016"],["59817.80","0.002"],["59817.90","0.002"],["65836.60","0.789"],["66132.00","0.019"],["66414.50","0.155"],["66427.70","0.267"],["66440.10","1.030"],["66450.70","1.364"],["66456.50","0.016"],["66457.70","0.188"],["66459.50","0.075"]],"a":[["66464.40","1.693"],["66467.20","0.173"],["66467.30","0.293"],["66467.50","0.166"],["66467.70","0.654"],["66468.40","0.303"],["66469.40","0.002"],["66470.90","0.601"],["66471.00","0.640"],["66472.40","0.301"],["66473.40","0.000"],["66473.80","0.000"],["66474.30","0.050"],["66474.80","0.302"],["66474.90","0.601"],["66475.10","0.312"],["66478.20","0.040"],["66480.10","0.042"],["66480.20","2.061"],["66480.40","0.028"],["66480.90","0.000"],["66481.20","0.000"],["66494.00","0.859"],["66499.10","0.000"],["66500.60","1.686"],["66504.00","0.159"],["66663.80","0.015"],["67188.00","10.369"],["67558.50","3.488"],["67693.90","0.904"],["73109.60","0.018"],["73110.90","0.004"],["99695.00","0.000"],["99696.60","0.004"]]}}
{"stream":"btcusdt@depth","data":{"e":"depthUpdate","E":1721818633002,"T":1721818633002,"s":"BTCUSDT","U":5013778638350,"u":5013778647192,"pu":5013778637886,"b":[["1000.00","623.302"],["5000.00","4.274"],["17223.60","0.028"],["33000.00","3.646"],["63141.00","0.000"],["63805.80","0.065"],["65365.20","2.705"],["65646.80","18.216"],["65831.80","0.761"],["66132.00","0.009"],["66164.30","0.008"],["66264.30","0.000"],["66421.10","0.007"],["66424.40","0.414"],["66427.70","0.249"],["66439.40","0.004"],["66444.20","1.745"],["66445.00","0.034"],["66450.20","0.005"],["66450.90","0.017"],["66455.20","0.003"],["66464.30","17.501"]],"a":[["66464.40","2.661"],["66466.20","0.168"],["66467.10","0.441"],["66467.70","0.636"],["66469.00","0.000"],["66474.10","0.002"],["66475.20","0.609"],["66475.60","0.846"],["66477.70","0.172"],["66488.80","0.677"],["66510.90","0.075"],["66764.40","0.000"],["67188.90","0.314"],["67561.10","0.872"],["68458.30","0.061"],["73098.20","0.000"],["73112.60","0.006"]]}}
{"stream":"btcusdt@depth","data":{"e":"depthUpdate","E":1721818633254,"T":1721818633254,"s":"BTCUSDT","U":5013778647233,"u":5013778658378,"pu":5013778647192,"b":[["1000.00","623.302"],["5000.00","4.274"],["17223.60","0.021"],["33000.00","3.646"],["59811.10","0.000"],["59816.70","0.014"],["59817.80","0.004"],["59819.70","0.002"],["63793.00","0.006"],["63805.80","0.065"],["63837.70","0.004"],["64470.40","0.057"],["66184.00","0.123"],["66430.00","0.645"],["66436.50","0.000"],["66441.40","0.190"],["66443.00","0.004"],["66449.70","0.714"],["66450.20","0.156"],["66450.80","0.332"],["66452.50","0.168"],["66454.30","1.284"],["66454.90","0.107"],["66458.20","0.017"],["66463.10","0.286"],["66464.30","17.665"]],"a":[["66464.40","2.361"],["66466.20","0.017"],["66466.40","0.026"],["66468.40","0.329"],["66473.90","0.645"],["66474.00","0.156"],["66474.10","0.000"],["66474.30","0.017"],["66474.40","0.032"],["66474.90","0.603"],["66475.00","0.350"],["66475.20","0.605"],["66478.00","0.404"],["66479.60","0.100"],["66480.40","0.002"],["66482.00","3.544"],["66488.50","0.121"],["66495.00","0.000"],["66498.90","1.686"],["66499.70","1.686"],["66499.90","0.000"],["66500.60","0.002"],["66798.60","0.002"],["67188.00","9.627"],["73100.50","0.000"],["73113.10","0.002"],["76434.00","0.018"]]}}
{"stream":"btcusdt@depth","data":{"e":"depthUpdate","E":1721818633505,"T":1721818633505,"s":"BTCUSDT","U":5013778658391,"u":5013778671565,"pu":5013778658378,"b":[["1000.00","623.302"],["5000.00","4.254"],["17223.60","0.021"],["33232.20","0.004"],["59813.20","0.014"],["59816.70","0.012"],["59817.80","0.006"],["59817.90","0.002"],["59819.80","0.002"],["66132.00","0.019"],["66459.50","0.075"],["66462.30","0.055"],["66462.90","0.065"],["66463.10","0.270"],["66464.30","17.673"],["66467.70","0.000"]],"a":[["66464.40","2.344"],["66465.90","0.021"],["66466.00","0.076"],["66466.10","0.000"],["66471.00","0.640"],["66479.60","0.100"],["66479.70","0.188"],["66481.20","0.004"],["66484.30","0.868"],["66491.00","0.023"],["66496.70","0.897"],["66497.60","0.002"],["66499.70","0.002"],["66500.80","1.699"],["66504.60","0.002"],["66507.80","0.487"],["66510.90","0.057"],["66514.80","0.000"],["66547.50","6.018"],["66663.80","0.015"],["66664.40","0.000"],["66744.00","0.300"],["67188.90","1.346"],["67196.50","0.218"],["67241.90","0.607"],["67394.90","0.217"],["76434.00","0.030"]]}}
{"stream":"btcusdt@depth","data":{"e":"depthUpdate","E":1721818633759,"T":1721818633758,"s":"BTCUSDT","U":5013778671675,"u":5013778678782,"pu":5013778671565,"b":[["1000.00","623.302"],["5000.00","4.274"],["17223.60","0.021"],["33000.00","3.646"],["59817.90","0.004"],["59833.00","0.018"],["65365.20","1.803"],["65474.00","0.806"],["65599.20","0.259"],["65685.80","0.000"],["65799.70","0.015"],["65838.60","1.517"],["65854.00","0.211"],["66132.00","0.009"],["66164.30","0.008"],["66427.70","0.098"],["66434.10","1.085"],["66434.80","0.007"],["66436.20","1.685"],["66436.30","0.000"],["66436.40","0.007"],["66437.20","0.098"],["66437.70","0.036"],["66437.90","0.023"],["66438.10","1.695"],["66439.30","0.000"],["66439.40","0.004"],["66441.50","0.000"],["66441.80","0.021"],["66443.20","1.745"],["66444.20","0.000"],["66444.50","0.833"],["66449.40","0.090"],["66450.20","0.153"],["66453.00","0.000"],["66454.00","0.008"],["66457.70","0.940"],["66463.10","0.244"],["66464.30","17.671"]],"a":[["66464.40","2.421"],["66464.90","0.278"],["66466.10","0.151"],["66467.00","0.443"],["66467.20","0.403"],["66467.40","0.275"],["66468.30","0.027"],["66469.10","0.000"],["66469.30","0.002"],["66470.90","0.000"],["66471.00","0.640"],["66473.80","0.601"],["66479.80","0.370"],["66481.20","0.000"],["66484.80","0.060"],["66486.50","0.000"],["66497.60","0.020"],["66503.00","0.007"],["66503.20","0.004"],["66503.70","0.139"],["66504.50","0.007"],["66504.90","0.000"],["66547.50","6.000"],["66663.80","0.015"],["66764.40","0.000"],["67074.00","0.213"],["67095.80","1.039"],["67188.90","1.703"],["67242.00","0.602"],["67385.70","0.451"],["73102.60","0.000"],["73109.60","0.014"],["73110.90","0.008"],["73113.00","0.004"]]}}
{"stream":"btcusdt@depth","data":{"e":"depthUpdate","E":1721818634012,"T":1721818634011,"s":"BTCUSDT","U":5013778678853,"u":5013778686578,"pu":5013778678782,"b":[["1000.00","623.302"],["5000.00","4.274"],["17223.60","0.021"],["59816.70","0.010"],["59817.80","0.008"],["63141.00","0.003"],["65407.60","0.252"],["65738.90","2.896"],["65832.00","1.545"],["66065.50","0.013"],["66132.00","0.019"],["66264.30","0.000"],["66385.70","0.349"],["66395.60","1.561"],["66414.50","0.439"],["66420.70","1.407"],["66420.80","0.002"],["66421.10","0.007"],["66421.20","0.099"],["66421.30","0.022"],["66423.20","0.041"],["66423.50","1.720"],["66426.00","0.041"],["66426.10","0.027"],["66426.50","0.870"],["66428.90","0.869"],["66430.30","0.046"],["66440.00","0.590"],["66441.40","0.039"],["66441.80","0.014"],["66449.70","1.015"],["66450.20","0.002"],["66450.80","0.150"],["66450.90","0.019"],["66451.90","0.175"],["66454.00","0.006"],["66462.80","0.208"],["66463.10","0.232"],["66464.10","0.000"],["66464.30","15.233"]],"a":[["66464.40","2.717"],["66464.60","1.114"],["66465.80","0.000"],["66466.40","0.026"],["66466.90","0.455"],["66467.30","0.520"],["66467.50","0.386"],["66467.70","0.636"],["66467.80","0.151"],["66468.30","0.029"],["66468.40","0.329"],["66469.60","0.936"],["66470.00","0.083"],["66470.60","0.038"],["66471.00","0.039"],["66471.10","1.633"],["66472.50","0.576"],["66473.00","0.002"],["66473.20","0.601"],["66473.40","0.002"],["66474.90","0.601"],["66476.70","0.013"],["66479.20","0.176"],["66481.20","0.000"],["66481.40","0.004"],["66484.70","0.020"],["66484.80","0.080"],["66484.90","0.097"],["66485.00","0.903"],["66485.20","0.025"],["66485.30","1.365"],["66492.90","0.023"],["66494.20","0.015"],["66497.60","0.002"],["66501.00","0.470"],["66504.30","1.205"],["66506.40","0.000"],["66508.30","0.305"],["66509.10","0.000"],["66510.30","0.038"],["66510.90","0.123"],["66511.00","0.107"],["66511.10","0.002"],["66511.20","47.993"],["66511.60","2.323"],["66513.30","0.056"],["66516.30","1.803"],["66516.40","0.084"],["66519.40","0.182"],["66524.50","0.868"],["66557.40","0.909"],["66562.90","0.000"],["66663.80","0.015"],["67129.10","0.025"],["67188.00","8.736"],["67388.30","0.890"]]}}
{"stream":"btcusdt@depth","data":{"e":"depthUpdate","E":1721818634266,"T":1721818634265,"s":"BTCUSDT","U":5013778687054,"u":5013778700610,"pu":5013778686578,"b":[["1000.00","623.302"],["5000.00","4.274"],["17223.60","0.021"],["33000.00","3.650"],["59816.70","0.008"],["59817.80","0.010"],["59817.90","0.000"],["59819.70","0.004"],["63141.10","0.006"],["65387.60","0.252"],["65686.70","0.304"],["65738.90","2.138"],["65739.80","0.758"],["65832.90","0.761"],["66132.00","0.009"],["66240.10","0.400"],["66240.20","0.452"],["66260.50","0.003"],["66306.60","1.200"],["66306.70","0.002"],["66406.60","0.006"],["66407.80","0.021"],["66423.50","0.035"],["66426.00","1.726"],["66427.70","0.116"],["66430.00","0.645"],["66434.10","0.045"],["66434.20","1.342"],["66436.50","0.000"],["66436.60","0.000"],["66438.10","0.010"],["66439.20","1.685"],["66443.00","0.004"],["66443.20","0.000"],["66444.50","0.046"],["66445.10","1.749"],["66449.70","0.714"],["66450.80","1.051"],["66450.90","0.017"],["66451.90","0.177"],["66452.50","0.136"],["66453.00","0.000"],["66454.80","1.000"],["66454.90","0.075"],["66455.80","0.036"],["66456.80","0.160"],["66463.10","0.230"],["66464.30","15.236"]],"a":[["66464.40","2.381"],["66467.20","0.173"],["66467.30","0.293"],["66467.40","0.047"],["66467.50","0.166"],["66468.30","0.027"],["66468.60","0.023"],["66469.60","0.938"],["66471.00","0.039"],["66474.00","0.124"],["66475.00","0.318"],["66476.70","0.009"],["66476.90","0.036"],["66477.40","0.054"],["66481.20","0.000"],["66482.00","3.544"],["66482.10","0.026"],["66484.80","0.077"],["66485.80","0.830"],["66487.70","0.000"],["66488.50","0.121"],["66489.40","0.300"],["66491.40","0.004"],["66494.10","0.023"],["66495.00","0.000"],["66496.90","0.009"],["66497.60","0.002"],["66498.10","0.285"],["66498.90","0.002"],["66499.50","0.023"],["66499.60","0.300"],["66499.70","1.686"],["66500.60","1.686"],["66500.80","0.015"],["66501.00","0.452"],["66501.50","0.000"],["66503.00","0.000"],["66504.60","0.009"],["66510.90","0.141"],["66511.10","1.685"],["66511.20","47.993"],["66511.50","0.040"],["66511.60","2.323"],["66516.10","0.054"],["66516.30","0.120"],["66516.40","0.084"],["66516.50","0.086"],["66516.70","0.063"],["66516.80","0.033"],["66519.40","0.182"],["66625.90","1.782"],["66627.10","0.028"],["66663.80","0.015"],["67188.90","2.594"]]}}
{"stream":"btcusdt@depth","data":{"e":"depthUpdate","E":1721818634532,"T":1721818634525,"s":"BTCUSDT","U":5013778701334,"u":5013778711067,"pu":5013778700610,"b":[["1000.00","623.302"],["5000.00","4.274"],["17223.60","0.021"],["33000.00","3.646"],["59816.70","0.006"],["59817.80","0.012"],["59817.90","0.002"],["65738.90","1.380"],["65739.80","1.516"],["65832.90","1.063"],["66132.00","0.019"],["66338.70","0.124"],["66385.70","0.116"],["66395.30","0.279"],["66423.50","0.033"],["66424.70","0.211"],["66427.70","0.116"],["66450.90","0.618"],["66451.00","0.294"],["66451.20","0.605"],["66463.10","0.228"],["66464.30","15.231"]],"a":[["66461.90","0.000"],["66464.40","2.379"],["66466.10","0.151"],["66466.40","0.000"],["66471.00","0.038"],["66473.00","0.153"],["66474.40","0.058"],["66478.40","0.046"],["66481.20","0.000"],["66487.70","0.018"],["66510.90","0.123"],["66519.40","0.182"],["66549.90","0.136"],["66550.00","10.957"],["66663.80","0.015"],["66664.40","0.000"],["67348.10","0.006"],["67452.20","3.626"],["67696.70","0.013"],["73109.60","0.010"],["73110.90","0.012"]]}}
{"stream":"btcusdt@depth","data":{"e":"depthUpdate","E":1721818634818,"T":1721818634816,"s":"BTCUSDT","U":5013778712117,"u":5013778719425,"pu":5013778711067,"b":[["1000.00","623.302"],["5000.00","4.274"],["17223.60","0.021"],["33000.00","3.646"],["33232.20","0.004"],["59816.70","0.004"],["59817.80","0.014"],["64700.00","39.958"],["65000.00","163.877"],["65300.00","157.281"],["65367.60","1.000"],["65739.80","2.274"],["66132.00","0.019"],["66164.30","0.008"],["66264.30","0.000"],["66338.70","0.124"],["66414.50","0.439"],["66437.50","1.361"],["66451.30","0.304"],["66461.70","0.002"],["66462.40","0.155"],["66468.30","0.000"]],"a":[["66464.40","2.142"],["66465.30","0.150"],["66466.00","0.076"],["66466.10","0.000"],["66467.20","0.002"],["66467.30","0.121"],["66467.50","0.000"],["66467.60","0.000"],["66471.00","0.039"],["66472.40","0.321"],["66473.40","0.000"],["66473.50","0.011"],["66474.00","0.126"],["66474.30","0.097"],["66474.80","0.401"],["66477.70","0.069"],["66477.90","0.748"],["66484.30","0.868"],["66487.70","0.000"],["66494.30","0.075"],["66627.20","0.008"],["66663.80","0.015"],["66764.40","0.000"],["66880.70","0.000"],["67050.00","11.389"],["76434.00","0.033"]]}}
{"stream":"btcusdt@depth","data":{"e":"depthUpdate","E":1721818635084,"T":1721818635084,"s":"BTCUSDT","U":5013778720245,"u":5013778730266,"pu":5013778719425,"b":[["1000.00","623.302"],["5000.00","4.274"],["17223.60","0.021"],["33000.00","3.646"],["33232.20","0.004"],["59817.90","0.000"],["63139.80","0.002"],["63139.90","0.000"],["63141.00","0.003"],["63141.10","0.008"],["64337.50","0.056"],["65387.70","0.113"],["65544.20","1.068"],["66132.00","0.029"],["66244.90","0.009"],["66409.80","38.189"],["66412.60","0.004"],["66414.50","0.451"],["66417.00","1.189"],["66421.10","0.027"],["66421.30","0.002"],["66423.50","0.033"],["66427.70","0.098"],["66430.00","0.645"],["66436.50","0.000"],["66443.00","0.004"],["66449.70","0.714"],["66450.70","1.364"],["66455.80","0.000"],["66456.80","0.161"],["66457.70","0.977"],["66459.50","0.075"],["66464.30","15.223"],["66464.90","0.000"]],"a":[["66464.40","2.299"],["66464.60","1.264"],["66465.30","0.000"],["66467.20","0.167"],["66467.30","0.291"],["66467.60","0.167"],["66467.80","0.164"],["66467.90","0.791"],["66468.40","0.303"],["66470.00","0.080"],["66471.00","0.038"],["66471.20","0.017"],["66474.00","0.124"],["66474.60","0.151"],["66474.70","0.040"],["66476.90","0.000"],["66477.40","0.018"],["66477.80","0.042"],["66478.00","0.004"],["66478.50","1.400"],["66482.00","3.544"],["66484.30","0.894"],["66484.70","0.000"],["66484.80","0.057"],["66484.90","0.097"],["66485.00","0.903"],["66485.10","0.101"],["66485.20","0.025"],["66485.30","1.365"],["66485.60","0.839"],["66485.70","0.022"],["66488.50","0.121"],["66495.00","0.000"],["66497.60","0.007"],["66501.50","0.000"],["66508.00","0.004"],["66511.10","0.002"],["66511.20","3.704"],["66514.40","46.193"],["66516.30","1.805"],["66516.40","0.084"],["66519.40","0.180"],["66663.80","0.015"],["66664.20","0.006"],["66809.80","0.002"],["66811.90","0.002"]]}}
{"stream":"btcusdt@depth","data":{"e":"depthUpdate","E":1721818635336,"T":1721818635329,"s":"BTCUSDT","U":5013778730277,"u":5013778745337,"pu":5013778730266,"b":[["1000.00","623.302"],["5000.00","4.274"],["17223.60","0.021"],["33000.00","3.646"],["63141.10","0.006"],["65367.60","1.901"],["66132.00","0.009"],["66244.90","0.019"],["66409.80","0.005"],["66409.90","0.007"],["66412.60","38.188"],["66412.70","0.004"],["66416.00","0.008"],["66416.80","0.012"],["66427.70","0.116"],["66437.60","0.080"],["66438.60","1.727"],["66438.80","0.141"],["66439.20","0.000"],["66445.50","0.011"],["66446.80","0.000"],["66449.10","0.000"],["66450.30","2.998"],["66450.40","0.002"],["66458.20","0.002"],["66461.60","0.150"],["66462.40","0.005"],["66464.30","15.084"]],"a":[["66464.40","2.301"],["66471.00","0.030"],["66473.70","0.061"],["66474.50","0.005"],["66500.60","0.002"],["66501.30","1.695"],["66509.70","0.623"],["66509.80","0.701"],["66510.90","0.265"],["66511.10","0.000"],["66513.10","0.002"],["66513.20","0.010"],["66513.30","44.809"],["66514.30","0.000"],["66514.40","1.440"],["66516.30","0.120"],["66517.60","0.728"],["66518.10","1.683"],["66519.40","0.182"],["66521.30","0.115"],["66522.50","0.085"],["66523.30","1.198"],["66663.80","0.000"],["66664.40","0.000"],["67328.90","0.509"],["67900.00","47.715"],["73103.70","0.000"],["73109.60","0.008"],["73110.90","0.014"],["73113.20","0.012"]]}}
{"stream":"btcusdt@depth","data":{"e":"depthUpdate","E":1721818635588,"T":1721818635587,"s":"BTCUSDT","U":5013778745652,"u":5013778753501,"pu":5013778745337,"b":[["1000.00","623.452"],["5000.00","4.274"],["17223.60","0.021"],["33232.20","0.010"],["59817.90","0.000"],["59818.30","0.007"],["59820.00","0.005"],["65367.60","2.803"],["65686.70","0.912"],["65832.90","1.366"],["66132.00","0.009"],["66338.70","0.005"],["66411.80","0.047"],["66415.40","0.004"],["66423.90","0.177"],["66424.00","0.014"],["66427.70","0.098"],["66434.10","1.085"],["66434.20","0.302"],["66434.80","0.007"],["66435.40","0.003"],["66435.60","0.000"],["66436.30","0.007"],["66436.40","0.007"],["66437.20","0.091"],["66438.00","0.065"],["66440.00","0.583"],["66440.20","0.007"],["66442.00","0.021"],["66443.90","1.763"],["66444.60","0.000"],["66445.10","0.004"],["66446.20","2.940"],["66447.70","0.589"],["66448.70","0.002"],["66449.10","0.002"],["66450.30","0.078"],["66450.40","0.000"],["66450.70","0.964"],["66451.30","0.302"],["66451.90","0.175"],["66452.20","0.000"],["66452.40","0.017"],["66453.10","0.756"],["66453.40","0.000"],["66454.30","1.282"],["66455.10","0.300"],["66464.30","15.042"]],"a":[["66464.40","2.286"],["66468.00","0.006"],["66468.30","0.023"],["66470.00","0.083"],["66471.00","0.039"],["66471.20","0.014"],["66474.00","0.126"],["66474.70","0.038"],["66476.90","0.003"],["66477.80","0.042"],["66478.20","0.037"],["66478.40","0.046"],["66480.10","0.046"],["66481.60","0.597"],["66482.10","0.028"],["66482.20","0.649"],["66482.90","1.162"],["66483.80","0.361"],["66484.30","0.912"],["66484.80","0.060"],["66485.70","0.025"],["66485.80","0.827"],["66487.10","0.029"],["66491.40","0.000"],["66492.00","0.008"],["66499.60","1.984"],["66501.30","0.011"],["66503.10","1.761"],["66503.20","0.004"],["66503.70","0.139"],["66503.90","0.053"],["66504.00","0.166"],["66504.60","0.002"],["66504.90","0.007"],["66505.70","0.000"],["66506.90","0.018"],["66507.80","0.480"],["66511.40","0.069"],["66511.50","0.040"],["66513.00","45.623"],["66513.10","0.002"],["66513.20","0.008"],["66513.30","0.056"],["66514.20","0.180"],["66514.80","0.002"],["66516.40","0.086"],["66516.50","0.086"],["66517.60","0.586"],["66519.40","0.182"],["66521.30","0.115"],["66617.80","0.344"],["66663.80","0.015"],["67449.20","0.591"],["67452.20","2.901"]]}}
{"stream":"btcusdt@depth","data":{"e":"depthUpdate","E":1721818635841,"T":1721818635817,"s":"BTCUSDT","U":5013778753551,"u":5013778760922,"pu":5013778753501,"b":[["1000.00","623.302"],["5000.00","4.274"],["17223.60","0.021"],["33000.00","3.646"],["33232.20","0.004"],["59833.00","0.018"],["63141.10","0.006"],["64337.50","0.002"],["65509.50","0.002"],["66132.00","0.019"],["66164.30","0.008"],["66264.30","0.000"],["66318.70","1.354"],["66338.70","0.124"],["66414.50","0.300"],["66415.00","0.595"],["66447.10","1.729"],["66447.70","0.591"],["66448.70","0.000"],["66450.70","1.364"]],"a":[["66471.00","0.039"],["66477.70","0.172"],["66477.90","0.645"],["66479.60","0.100"],["66484.30","0.894"],["66512.90","0.062"],["66514.20","0.038"],["66516.40","0.084"],["66563.20","0.980"],["66663.80","0.015"],["66764.40","0.000"],["67188.00","8.141"],["67507.30","0.062"],["67558.50","2.616"],["68600.00","10.976"]]}}
{"stream":"btcusdt@depth","data":{"e":"depthUpdate","E":1721818636109,"T":1721818636108,"s":"BTCUSDT","U":5013778761854,"u":5013778769406,"pu":5013778760922,"b":[["1000.00","623.302"],["5000.00","4.254"],["17223.60","0.021"],["33232.20","0.010"],["65030.30","0.000"],["65854.00","0.011"],["66132.00","0.019"],["66184.00","0.023"],["66318.90","0.944"],["66414.50","0.451"],["66417.00","1.189"],["66423.50","0.033"],["66427.70","0.116"],["66430.00","0.645"],["66436.50","0.000"],["66443.00","0.004"],["66446.20","0.000"],["66446.30","3.095"],["66447.10","0.400"],["66449.10","0.000"],["66449.70","0.714"],["66450.20","0.002"],["66450.30","0.080"],["66450.70","1.366"],["66451.60","0.022"],["66452.50","0.138"],["66453.40","0.002"],["66454.30","1.284"],["66455.90","0.055"],["66456.80","0.124"],["66456.90","1.157"],["66457.70","0.940"],["66463.20","1.761"],["66464.30","15.049"]],"a":[["66464.40","2.380"],["66465.90","0.172"],["66467.20","0.002"],["66467.30","0.121"],["66467.50","0.171"],["66471.00","0.039"],["66474.60","0.000"],["66477.00","0.055"],["66477.50","0.162"],["66477.80","0.005"],["66478.50","1.363"],["66481.20","0.004"],["66482.00","3.544"],["66488.50","0.121"],["66495.00","0.000"],["66499.60","0.300"],["66500.90","1.786"],["66501.50","0.000"],["66508.00","0.004"],["66509.70","0.552"],["66510.90","0.922"],["66512.90","0.060"],["66513.00","0.870"],["66513.10","45.223"],["66513.20","0.008"],["66514.20","0.038"],["66516.60","0.047"],["66516.70","0.063"],["66517.60","0.000"],["66521.30","0.115"],["66663.80","0.015"],["66744.00","0.200"],["67074.00","0.013"],["67188.90","3.189"],["73110.90","0.012"],["73113.10","0.004"]]}}
